2023-10-09 14:23:14,476 - instabot version: 0.117.0 (bot) - INFO - Instabot version: 0.117.0 Started
2023-10-09 14:23:14,476 - instabot version: 0.117.0 (bot) - DEBUG - Bot imported from C:\Users\Admin\AppData\Roaming\Python\Python310\site-packages\instabot\bot\bot.py
2023-10-09 14:23:14,476 - instabot version: 0.117.0 (api_login) - INFO - Not yet logged in starting: PRE-LOGIN FLOW!
2023-10-09 14:23:25,545 - instabot version: 0.117.0 (api) - WARNING - HTTPSConnectionPool(host='i.instagram.com', port=443): Max retries exceeded with url: /api/v1/accounts/get_prefill_candidates/ (Caused by NewConnectionError('<urllib3.connection.HTTPSConnection object at 0x000002357497F4F0>: Failed to establish a new connection: [Errno 11001] getaddrinfo failed'))
2023-10-09 14:23:36,606 - instabot version: 0.117.0 (api) - WARNING - HTTPSConnectionPool(host='i.instagram.com', port=443): Max retries exceeded with url: /api/v1/qe/sync/ (Caused by NewConnectionError('<urllib3.connection.HTTPSConnection object at 0x000002357497F730>: Failed to establish a new connection: [Errno 11001] getaddrinfo failed'))
2023-10-09 14:23:47,654 - instabot version: 0.117.0 (api) - WARNING - HTTPSConnectionPool(host='i.instagram.com', port=443): Max retries exceeded with url: /api/v1/launcher/sync/ (Caused by NewConnectionError('<urllib3.connection.HTTPSConnection object at 0x000002357497F6A0>: Failed to establish a new connection: [Errno 11001] getaddrinfo failed'))
2023-10-09 14:23:58,718 - instabot version: 0.117.0 (api) - WARNING - HTTPSConnectionPool(host='i.instagram.com', port=443): Max retries exceeded with url: /api/v1/accounts/contact_point_prefill/ (Caused by NewConnectionError('<urllib3.connection.HTTPSConnection object at 0x000002357497EEC0>: Failed to establish a new connection: [Errno 11001] getaddrinfo failed'))
